2018-12-16 20:23:51,602 ERROR: Exception on /edit_profile [POST] [in C:\exercise\microblog\venv\lib\site-packages\flask\app.py:1761]
Traceback (most recent call last):
  File "C:\exercise\microblog\venv\lib\site-packages\sqlalchemy\engine\base.py", line 1193, in _execute_context
    context)
  File "C:\exercise\microblog\venv\lib\site-packages\sqlalchemy\engine\default.py", line 509, in do_execute
    cursor.execute(statement, parameters)
sqlite3.IntegrityError: UNIQUE constraint failed: user.username

The above exception was the direct cause of the following exception:

Traceback (most recent call last):
  File "C:\exercise\microblog\venv\lib\site-packages\flask\app.py", line 2292, in wsgi_app
    response = self.full_dispatch_request()
  File "C:\exercise\microblog\venv\lib\site-packages\flask\app.py", line 1815, in full_dispatch_request
    rv = self.handle_user_exception(e)
  File "C:\exercise\microblog\venv\lib\site-packages\flask\app.py", line 1718, in handle_user_exception
    reraise(exc_type, exc_value, tb)
  File "C:\exercise\microblog\venv\lib\site-packages\flask\_compat.py", line 35, in reraise
    raise value
  File "C:\exercise\microblog\venv\lib\site-packages\flask\app.py", line 1813, in full_dispatch_request
    rv = self.dispatch_request()
  File "C:\exercise\microblog\venv\lib\site-packages\flask\app.py", line 1799, in dispatch_request
    return self.view_functions[rule.endpoint](**req.view_args)
  File "C:\exercise\microblog\app\routes.py", line 56, in edit_profile
    db.session.commit()
  File "C:\exercise\microblog\venv\lib\site-packages\sqlalchemy\orm\scoping.py", line 153, in do
    return getattr(self.registry(), name)(*args, **kwargs)
  File "C:\exercise\microblog\venv\lib\site-packages\sqlalchemy\orm\session.py", line 954, in commit
    self.transaction.commit()
  File "C:\exercise\microblog\venv\lib\site-packages\sqlalchemy\orm\session.py", line 467, in commit
    self._prepare_impl()
  File "C:\exercise\microblog\venv\lib\site-packages\sqlalchemy\orm\session.py", line 447, in _prepare_impl
    self.session.flush()
  File "C:\exercise\microblog\venv\lib\site-packages\sqlalchemy\orm\session.py", line 2313, in flush
    self._flush(objects)
  File "C:\exercise\microblog\venv\lib\site-packages\sqlalchemy\orm\session.py", line 2440, in _flush
    transaction.rollback(_capture_exception=True)
  File "C:\exercise\microblog\venv\lib\site-packages\sqlalchemy\util\langhelpers.py", line 66, in __exit__
    compat.reraise(exc_type, exc_value, exc_tb)
  File "C:\exercise\microblog\venv\lib\site-packages\sqlalchemy\util\compat.py", line 249, in reraise
    raise value
  File "C:\exercise\microblog\venv\lib\site-packages\sqlalchemy\orm\session.py", line 2404, in _flush
    flush_context.execute()
  File "C:\exercise\microblog\venv\lib\site-packages\sqlalchemy\orm\unitofwork.py", line 395, in execute
    rec.execute(self)
  File "C:\exercise\microblog\venv\lib\site-packages\sqlalchemy\orm\unitofwork.py", line 560, in execute
    uow
  File "C:\exercise\microblog\venv\lib\site-packages\sqlalchemy\orm\persistence.py", line 177, in save_obj
    mapper, table, update)
  File "C:\exercise\microblog\venv\lib\site-packages\sqlalchemy\orm\persistence.py", line 774, in _emit_update_statements
    execute(statement, multiparams)
  File "C:\exercise\microblog\venv\lib\site-packages\sqlalchemy\engine\base.py", line 948, in execute
    return meth(self, multiparams, params)
  File "C:\exercise\microblog\venv\lib\site-packages\sqlalchemy\sql\elements.py", line 269, in _execute_on_connection
    return connection._execute_clauseelement(self, multiparams, params)
  File "C:\exercise\microblog\venv\lib\site-packages\sqlalchemy\engine\base.py", line 1060, in _execute_clauseelement
    compiled_sql, distilled_params
  File "C:\exercise\microblog\venv\lib\site-packages\sqlalchemy\engine\base.py", line 1200, in _execute_context
    context)
  File "C:\exercise\microblog\venv\lib\site-packages\sqlalchemy\engine\base.py", line 1413, in _handle_dbapi_exception
    exc_info
  File "C:\exercise\microblog\venv\lib\site-packages\sqlalchemy\util\compat.py", line 265, in raise_from_cause
    reraise(type(exception), exception, tb=exc_tb, cause=cause)
  File "C:\exercise\microblog\venv\lib\site-packages\sqlalchemy\util\compat.py", line 248, in reraise
    raise value.with_traceback(tb)
  File "C:\exercise\microblog\venv\lib\site-packages\sqlalchemy\engine\base.py", line 1193, in _execute_context
    context)
  File "C:\exercise\microblog\venv\lib\site-packages\sqlalchemy\engine\default.py", line 509, in do_execute
    cursor.execute(statement, parameters)
sqlalchemy.exc.IntegrityError: (sqlite3.IntegrityError) UNIQUE constraint failed: user.username [SQL: 'UPDATE user SET username=?, about_me=? WHERE user.id = ?'] [parameters: ('cuong', 'testfdstest', 4)] (Background on this error at: http://sqlalche.me/e/gkpj)
2018-12-16 20:24:21,675 INFO: Microblog startup [in C:\exercise\microblog\app\logging.py:15]
2018-12-16 20:24:22,806 INFO: Microblog startup [in C:\exercise\microblog\app\logging.py:15]
2018-12-16 20:57:11,944 INFO: Microblog startup [in C:\exercise\microblog\app\logging.py:15]
2018-12-16 20:57:24,070 INFO: Microblog startup [in C:\exercise\microblog\app\logging.py:15]
2018-12-16 20:57:25,166 INFO: Microblog startup [in C:\exercise\microblog\app\logging.py:15]
2018-12-16 20:58:08,645 INFO: Microblog startup [in C:\exercise\microblog\app\logging.py:15]
2018-12-16 20:58:53,115 INFO: Microblog startup [in C:\exercise\microblog\app\logging.py:15]
2018-12-16 21:00:00,354 INFO: Microblog startup [in C:\exercise\microblog\app\logging.py:15]
2018-12-16 21:00:11,388 INFO: Microblog startup [in C:\exercise\microblog\app\logging.py:15]
2018-12-16 21:00:15,833 INFO: Microblog startup [in C:\exercise\microblog\app\logging.py:15]
